<?xml version="0.8" encoding="utf-8"?>
<robot name="hector_description">
    <!-- transmission -->
    <transmission name="l_hip_yaw_tran">
        <type>transmission_interface/SimpleTransmission</type>
        <joint name="l_hip_yaw_joint">
            <hardwareInterface>hardware_interface/EffortJointInterface</hardwareInterface>
        </joint>
        <actuator name="l_hip_yaw_motor">
            <hardwareInterface>hardware_interface/EffortJointInterface</hardwareInterface>
            <mechanicalReduction>1</mechanicalReduction>
        </actuator>
    </transmission>
    <transmission name="l_hip_roll_tran">
        <type>transmission_interface/SimpleTransmission</type>
        <joint name="l_hip_roll_joint">
            <hardwareInterface>hardware_interface/EffortJointInterface</hardwareInterface>
        </joint>
        <actuator name="l_hip_roll_motor">
            <hardwareInterface>hardware_interface/EffortJointInterface</hardwareInterface>
            <mechanicalReduction>1</mechanicalReduction>
        </actuator>
    </transmission>
    <transmission name="l_thigh_tran">
        <type>transmission_interface/SimpleTransmission</type>
        <joint name="l_thigh_joint">
            <hardwareInterface>hardware_interface/EffortJointInterface</hardwareInterface>
        </joint>
        <actuator name="l_thigh_motor">
            <hardwareInterface>hardware_interface/EffortJointInterface</hardwareInterface>
            <mechanicalReduction>1</mechanicalReduction>
        </actuator>
    </transmission>
    <transmission name="l_calf_tran">
        <type>transmission_interface/SimpleTransmission</type>
        <joint name="l_calf_joint">
            <hardwareInterface>hardware_interface/EffortJointInterface</hardwareInterface>
        </joint>
        <actuator name="l_calf_motor">
            <hardwareInterface>hardware_interface/EffortJointInterface</hardwareInterface>
            <mechanicalReduction>1</mechanicalReduction>
        </actuator>
    </transmission>
    <transmission name="l_ankle_pitch_tran">
        <type>transmission_interface/SimpleTransmission</type>
        <joint name="l_ankle_pitch_joint">
            <hardwareInterface>hardware_interface/EffortJointInterface</hardwareInterface>
        </joint>
        <actuator name="l_ankle_pitch_motor">
            <hardwareInterface>hardware_interface/EffortJointInterface</hardwareInterface>
            <mechanicalReduction>1</mechanicalReduction>
        </actuator>
    </transmission>
    <!-- <transmission name="l_ankle_roll_tran">
        <type>transmission_interface/SimpleTransmission</type>
        <joint name="l_ankle_roll_joint">
            <hardwareInterface>hardware_interface/EffortJointInterface</hardwareInterface>
        </joint>
        <actuator name="l_ankle_roll_motor">
            <hardwareInterface>hardware_interface/EffortJointInterface</hardwareInterface>
            <mechanicalReduction>1</mechanicalReduction>
        </actuator>
    </transmission> -->
    <transmission name="r_hip_yaw_tran">
        <type>transmission_interface/SimpleTransmission</type>
        <joint name="r_hip_yaw_joint">
            <hardwareInterface>hardware_interface/EffortJointInterface</hardwareInterface>
        </joint>
        <actuator name="r_hip_yaw_motor">
            <hardwareInterface>hardware_interface/EffortJointInterface</hardwareInterface>
            <mechanicalReduction>1</mechanicalReduction>
        </actuator>
    </transmission>
    <transmission name="r_hip_roll_tran">
        <type>transmission_interface/SimpleTransmission</type>
        <joint name="r_hip_roll_joint">
            <hardwareInterface>hardware_interface/EffortJointInterface</hardwareInterface>
        </joint>
        <actuator name="r_hip_roll_motor">
            <hardwareInterface>hardware_interface/EffortJointInterface</hardwareInterface>
            <mechanicalReduction>1</mechanicalReduction>
        </actuator>
    </transmission>
    <transmission name="r_thigh_tran">
        <type>transmission_interface/SimpleTransmission</type>
        <joint name="r_thigh_joint">
            <hardwareInterface>hardware_interface/EffortJointInterface</hardwareInterface>
        </joint>
        <actuator name="r_thigh_motor">
            <hardwareInterface>hardware_interface/EffortJointInterface</hardwareInterface>
            <mechanicalReduction>1</mechanicalReduction>
        </actuator>
    </transmission>
    <transmission name="r_calf_tran">
        <type>transmission_interface/SimpleTransmission</type>
        <joint name="r_calf_joint">
            <hardwareInterface>hardware_interface/EffortJointInterface</hardwareInterface>
        </joint>
        <actuator name="r_calf_motor">
            <hardwareInterface>hardware_interface/EffortJointInterface</hardwareInterface>
            <mechanicalReduction>1</mechanicalReduction>
        </actuator>
    </transmission>
    <transmission name="r_ankle_pitch_tran">
        <type>transmission_interface/SimpleTransmission</type>
        <joint name="r_ankle_pitch_joint">
            <hardwareInterface>hardware_interface/EffortJointInterface</hardwareInterface>
        </joint>
        <actuator name="r_ankle_pitch_motor">
            <hardwareInterface>hardware_interface/EffortJointInterface</hardwareInterface>
            <mechanicalReduction>1</mechanicalReduction>
        </actuator>
    </transmission>
    <!-- <transmission name="r_ankle_roll_tran">
        <type>transmission_interface/SimpleTransmission</type>
        <joint name="r_ankle_roll_joint">
            <hardwareInterface>hardware_interface/EffortJointInterface</hardwareInterface>
        </joint>
        <actuator name="r_ankle_roll_motor">
            <hardwareInterface>hardware_interface/EffortJointInterface</hardwareInterface>
            <mechanicalReduction>1</mechanicalReduction>
        </actuator>
    </transmission> -->

    <gazebo>
        <plugin name="gazebo_ros_control" filename="libgazebo_ros_control.so">
            <robotNamespace>/hector_gazebo</robotNamespace>
            <robotSimType>gazebo_ros_control/DefaultRobotHWSim</robotSimType>
        </plugin>
    </gazebo>

    <!-- <gazebo>
        <plugin name="3dplot" filename="libLinkPlot3DPlugin.so">
            <frequency>10</frequency>
            <plot>
                <link>base_link</link>
                <pose>0 0 0 0 0 0</pose>
                <material>Gazebo/Yellow</material>
            </plot>
        </plugin>
    </gazebo> -->

    <gazebo>
        <plugin filename="libgazebo_ros_force.so" name="gazebo_ros_force">
            <bodyName>base_link</bodyName>
            <topicName>/apply_force/base_link</topicName>
        </plugin>
    </gazebo>

    <gazebo reference="l_ankle_roll_link">
        <material>Gazebo/Black</material>
        <mu1>0.8</mu1> <!-- 摩擦系数1 -->
        <mu2>0.8</mu2> <!-- 摩擦系数2 -->
    </gazebo>
    <gazebo reference="l_ankle_roll_link">
		<material>Gazebo/Black</material>
		<mu1>0.8</mu1> <!-- 摩擦系数1 -->
		<mu2>0.8</mu2> <!-- 摩擦系数2 -->
    </gazebo>


	<link name="base_link">
		<inertial>
			<origin xyz="0.036389 -1.95E-05 0.0235966" rpy="0 0 0" />
			<mass value="1.4140796" />
			<inertia ixx="0.0052145" ixy="3.8E-06" ixz="0.0003997" iyy="0.0041695" iyz="6E-07" izz="0.007904" />
		</inertial>
		<visual>
			<origin xyz="0 0 0" rpy="0 0 0" />
			<geometry>
				<mesh filename="package://pai_12dof_v2_0312/meshes/base_link.STL" />
			</geometry>
			<material name="">
				<color rgba="0.75294 0.75294 0.75294 1" />
			</material>
		</visual>
		<collision>
			<origin xyz="0 0 0" rpy="0 0 0" />
			<geometry>
				<mesh filename="package://pai_12dof_v2_0312/meshes/base_link.STL" />
			</geometry>
		</collision>
	</link>
	<link name="r_hip_yaw_link">
		<inertial>
			<origin xyz="-0.0578492 0 -0.0416749" rpy="0 0 0" />
			<mass value="0.3887654" />
			<inertia ixx="0.0002521" ixy="0" ixz="-0.0001456" iyy="0.0004324" iyz="0" izz="0.0003133" />
		</inertial>
		<visual>
			<origin xyz="0 0 0" rpy="0 0 0" />
			<geometry>
				<mesh filename="package://pai_12dof_v2_0312/meshes/r_hip_yaw_link.STL" />
			</geometry>
			<material name="">
				<color rgba="0.75294 0.75294 0.75294 1" />
			</material>
		</visual>
		<collision>
			<origin xyz="0 0 0" rpy="0 0 0" />
			<geometry>
				<mesh filename="package://pai_12dof_v2_0312/meshes/r_hip_yaw_link.STL" />
			</geometry>
		</collision>
	</link>
	<joint name="r_hip_yaw_joint" type="revolute">
		<origin xyz="0 -0.075 0" rpy="0 0 0" />
		<parent link="base_link" />
		<child link="r_hip_yaw_link" />
		<axis xyz="0 0 1" />
		<limit lower="-0.8" upper="0.8" effort="21" velocity="21" />
	</joint>
	<link name="r_hip_roll_link">
		<inertial>
			<origin xyz="0.0373373 0.0004272 0.0004287" rpy="0 0 0" />
			<mass value="0.7495221" />
			<inertia ixx="0.0013819" ixy="-3E-06" ixz="5.4E-06" iyy="0.0003384" iyz="6E-07" izz="0.0014434" />
		</inertial>
		<visual>
			<origin xyz="0 0 0" rpy="0 0 0" />
			<geometry>
				<mesh filename="package://pai_12dof_v2_0312/meshes/r_hip_roll_link.STL" />
			</geometry>
			<material name="">
				<color rgba="0.75294 0.75294 0.75294 1" />
			</material>
		</visual>
		<collision>
			<origin xyz="0 0 0" rpy="0 0 0" />
			<geometry>
				<mesh filename="package://pai_12dof_v2_0312/meshes/r_hip_roll_link.STL" />
			</geometry>
		</collision>
	</link>
	<joint name="r_hip_roll_joint" type="revolute">
		<origin xyz="-0.04 0 -0.05" rpy="0 0 0" />
		<parent link="r_hip_yaw_link" />
		<child link="r_hip_roll_link" />
		<axis xyz="1 0 0" />
		<limit lower="-0.5" upper="0.2" effort="21" velocity="21" />
	</joint>
	<link name="r_thigh_link">
		<inertial>
			<origin xyz="0.004364 -0.0013366 -0.0465535" rpy="0 0 0" />
			<mass value="0.1443603" />
			<inertia ixx="0.0004365" ixy="-8E-07" ixz="3.66E-05" iyy="0.0004422" iyz="9E-06" izz="4.91E-05" />
		</inertial>
		<visual>
			<origin xyz="0 0 0" rpy="0 0 0" />
			<geometry>
				<mesh filename="package://pai_12dof_v2_0312/meshes/r_thigh_link.STL" />
			</geometry>
			<material name="">
				<color rgba="0.75294 0.75294 0.75294 1" />
			</material>
		</visual>
		<collision>
			<origin xyz="0 0 0" rpy="0 0 0" />
			<geometry>
				<mesh filename="package://pai_12dof_v2_0312/meshes/r_thigh_link.STL" />
			</geometry>
		</collision>
	</link>
	<joint name="r_thigh_joint" type="revolute">
		<origin xyz="0.04 0 0" rpy="0 -0.25 0" />
		<parent link="r_hip_roll_link" />
		<child link="r_thigh_link" />
		<axis xyz="0 1 0" />
		<limit lower="-0.8" upper="0.44" effort="21" velocity="21" />
	</joint>
	<link name="r_calf_link">
		<inertial>
			<origin xyz="0.0035389 0 -0.0714471" rpy="0 0 0" />
			<mass value="0.768122" />
			<inertia ixx="0.0010371" ixy="0" ixz="-9.4E-06" iyy="0.0010674" iyz="-3.3E-06" izz="0.0002151" />
		</inertial>
		<visual>
			<origin xyz="0 0 0" rpy="0 0 0" />
			<geometry>
				<mesh filename="package://pai_12dof_v2_0312/meshes/r_calf_link.STL" />
			</geometry>
			<material name="">
				<color rgba="0.75294 0.75294 0.75294 1" />
			</material>
		</visual>
		<collision>
			<origin xyz="0 0 0" rpy="0 0 0" />
			<geometry>
				<mesh filename="package://pai_12dof_v2_0312/meshes/r_calf_link.STL" />
			</geometry>
		</collision>
	</link>
	<joint name="r_calf_joint" type="revolute">
		<origin xyz="0.014 0 -0.14935" rpy="0 0.5 0" />
		<parent link="r_thigh_link" />
		<child link="r_calf_link" />
		<axis xyz="0 1 0" />
		<limit lower="-0.5" upper="1.48" effort="21" velocity="21" />
	</joint>
	<link name="r_ankle_pitch_link">
		<inertial>
			<origin xyz="0 0 0" rpy="0 0 0" />
			<mass value="0.0088647" />
			<inertia ixx="2E-07" ixy="0" ixz="0" iyy="1E-06" iyz="0" izz="1E-06" />
		</inertial>
		<visual>
			<origin xyz="0 0 0" rpy="0 0 0" />
			<geometry>
				<mesh filename="package://pai_12dof_v2_0312/meshes/r_ankle_pitch_link.STL" />
			</geometry>
			<material name="">
				<color rgba="0.75294 0.75294 0.75294 1" />
			</material>
		</visual>
		<collision>
			<origin xyz="0 0 0" rpy="0 0 0" />
			<geometry>
				<mesh filename="package://pai_12dof_v2_0312/meshes/r_ankle_pitch_link.STL" />
			</geometry>
		</collision>
	</link>
	<joint name="r_ankle_pitch_joint" type="revolute">
		<origin xyz="0.0025 0 -0.15845" rpy="0 -0.25 0" />
		<parent link="r_calf_link" />
		<child link="r_ankle_pitch_link" />
		<axis xyz="0 1 0" />
		<limit lower="-0.62" upper="0.65" effort="21" velocity="21" />
	</joint>
	<link name="r_ankle_roll_link">
		<inertial>
			<origin xyz="0.0240775 0 -0.018709" rpy="0 0 0" />
			<mass value="0.1728932" />
			<inertia ixx="7.78E-05" ixy="0" ixz="2.11E-05" iyy="0.0003287" iyz="0" izz="0.0003779" />
		</inertial>
		<visual>
			<origin xyz="0 0 0" rpy="0 0 0" />
			<geometry>
				<mesh filename="package://pai_12dof_v2_0312/meshes/r_ankle_roll_link.STL" />
			</geometry>
			<material name="">
				<color rgba="0.75294 0.75294 0.75294 1" />
			</material>
		</visual>
		<collision>
			<origin xyz="0 0 0" rpy="0 0 0" />
			<geometry>
				<mesh filename="package://pai_12dof_v2_0312/meshes/r_ankle_roll_link.STL" />
			</geometry>
		</collision>
	</link>
	<joint name="r_ankle_roll_joint" type="fixed">
		<origin xyz="0 0 0" rpy="0 0 0" />
		<parent link="r_ankle_pitch_link" />
		<child link="r_ankle_roll_link" />
		<axis xyz="1 0 0" />
		<limit lower="-0.2" upper="0.5" effort="21" velocity="21" />
	</joint>
	<link name="l_hip_yaw_link">
		<inertial>
			<origin xyz="-0.0578492 0 -0.0416749" rpy="0 0 0" />
			<mass value="0.19436" />
			<inertia ixx="0.0002521" ixy="0" ixz="-0.0001456" iyy="0.0004324" iyz="0" izz="0.0003133" />
		</inertial>
		<visual>
			<origin xyz="0 0 0" rpy="0 0 0" />
			<geometry>
				<mesh filename="package://pai_12dof_v2_0312/meshes/l_hip_yaw_link.STL" />
			</geometry>
			<material name="">
				<color rgba="0.75294 0.75294 0.75294 1" />
			</material>
		</visual>
		<collision>
			<origin xyz="0 0 0" rpy="0 0 0" />
			<geometry>
				<mesh filename="package://pai_12dof_v2_0312/meshes/l_hip_yaw_link.STL" />
			</geometry>
		</collision>
	</link>
	<joint name="l_hip_yaw_joint" type="revolute">
		<origin xyz="0 0.075 0" rpy="0 0 0" />
		<parent link="base_link" />
		<child link="l_hip_yaw_link" />
		<axis xyz="0 0 1" />
		<limit lower="-0.8" upper="0.8" effort="21" velocity="21" />
	</joint>
	<link name="l_hip_roll_link">
		<inertial>
			<origin xyz="0.0373373 -0.0004323 0.0004287" rpy="0 0 0" />
			<mass value="0.74952" />
			<inertia ixx="0.0013819" ixy="-1.6E-06" ixz="5.4E-06" iyy="0.0003384" iyz="2E-07" izz="0.0014434" />
		</inertial>
		<visual>
			<origin xyz="0 0 0" rpy="0 0 0" />
			<geometry>
				<mesh filename="package://pai_12dof_v2_0312/meshes/l_hip_roll_link.STL" />
			</geometry>
			<material name="">
				<color rgba="0.75294 0.75294 0.75294 1" />
			</material>
		</visual>
		<collision>
			<origin xyz="0 0 0" rpy="0 0 0" />
			<geometry>
				<mesh filename="package://pai_12dof_v2_0312/meshes/l_hip_roll_link.STL" />
			</geometry>
		</collision>
	</link>
	<joint name="l_hip_roll_joint" type="revolute">
		<origin xyz="-0.04 0 -0.05" rpy="0 0 0" />
		<parent link="l_hip_yaw_link" />
		<child link="l_hip_roll_link" />
		<axis xyz="1 0 0" />
		<limit lower="-0.2" upper="0.5" effort="21" velocity="21" />
	</joint>
	<link name="l_thigh_link">
		<inertial>
			<origin xyz="0.004364 0.0013366 -0.046554" rpy="0 0 0" />
			<mass value="0.1443603" />
			<inertia ixx="0.0004365" ixy="8E-07" ixz="3.66E-05" iyy="0.0004422" iyz="-9E-06" izz="4.91E-05" />
		</inertial>
		<visual>
			<origin xyz="0 0 0" rpy="0 0 0" />
			<geometry>
				<mesh filename="package://pai_12dof_v2_0312/meshes/l_thigh_link.STL" />
			</geometry>
			<material name="">
				<color rgba="0.75294 0.75294 0.75294 1" />
			</material>
		</visual>
		<collision>
			<origin xyz="0 0 0" rpy="0 0 0" />
			<geometry>
				<mesh filename="package://pai_12dof_v2_0312/meshes/l_thigh_link.STL" />
			</geometry>
		</collision>
	</link>
	<joint name="l_thigh_joint" type="revolute">
		<origin xyz="0.04 0 0" rpy="0 -0.25 0" />
		<parent link="l_hip_roll_link" />
		<child link="l_thigh_link" />
		<axis xyz="0 1 0" />
		<limit lower="-0.8" upper="0.44" effort="21" velocity="21" />
	</joint>
	<link name="l_calf_link">
		<inertial>
			<origin xyz="0.0035389 0 -0.07142" rpy="0 0 0" />
			<mass value="0.768122" />
			<inertia ixx="0.0010371" ixy="0" ixz="-9.4E-06" iyy="0.0010674" iyz="-3.3E-06" izz="0.0002151" />
		</inertial>
		<visual>
			<origin xyz="0 0 0" rpy="0 0 0" />
			<geometry>
				<mesh filename="package://pai_12dof_v2_0312/meshes/l_calf_link.STL" />
			</geometry>
			<material name="">
				<color rgba="0.75294 0.75294 0.75294 1" />
			</material>
		</visual>
		<collision>
			<origin xyz="0 0 0" rpy="0 0 0" />
			<geometry>
				<mesh filename="package://pai_12dof_v2_0312/meshes/l_calf_link.STL" />
			</geometry>
		</collision>
	</link>
	<joint name="l_calf_joint" type="revolute">
		<origin xyz="0.014 0 -0.14935" rpy="0 0.5 0" />
		<parent link="l_thigh_link" />
		<child link="l_calf_link" />
		<axis xyz="0 1 0" />
		<limit lower="-0.5" upper="1.48" effort="21" velocity="21" />
	</joint>
	<link name="l_ankle_pitch_link">
		<inertial>
			<origin xyz="0 0 0" rpy="0 0 0" />
			<mass value="0.0088647" />
			<inertia ixx="2E-07" ixy="0" ixz="0" iyy="1E-06" iyz="0" izz="1E-06" />
		</inertial>
		<visual>
			<origin xyz="0 0 0" rpy="0 0 0" />
			<geometry>
				<mesh filename="package://pai_12dof_v2_0312/meshes/l_ankle_pitch_link.STL" />
			</geometry>
			<material name="">
				<color rgba="0.75294 0.75294 0.75294 1" />
			</material>
		</visual>
		<collision>
			<origin xyz="0 0 0" rpy="0 0 0" />
			<geometry>
				<mesh filename="package://pai_12dof_v2_0312/meshes/l_ankle_pitch_link.STL" />
			</geometry>
		</collision>
	</link>
	<joint name="l_ankle_pitch_joint" type="revolute">
		<origin xyz="0.0025 0 -0.15845" rpy="0 -0.25 0" />
		<parent link="l_calf_link" />
		<child link="l_ankle_pitch_link" />
		<axis xyz="0 1 0" />
		<limit lower="-0.62" upper="0.65" effort="21" velocity="21" />
	</joint>
	<link name="l_ankle_roll_link">
		<inertial>
			<origin xyz="0.0240775 0 -0.018709" rpy="0 0 0" />
			<mass value="0.1728932" />
			<inertia ixx="7.78E-05" ixy="0" ixz="2.11E-05" iyy="0.0003287" iyz="0" izz="0.0003779" />
		</inertial>
		<visual>
			<origin xyz="0 0 0" rpy="0 0 0" />
			<geometry>
				<mesh filename="package://pai_12dof_v2_0312/meshes/l_ankle_roll_link.STL" />
			</geometry>
			<material name="">
				<color rgba="0.75294 0.75294 0.75294 1" />
			</material>
		</visual>
		<collision>
			<origin xyz="0 0 0" rpy="0 0 0" />
			<geometry>
				<mesh filename="package://pai_12dof_v2_0312/meshes/l_ankle_roll_link.STL" />
			</geometry>
		</collision>
	</link>
	<joint name="l_ankle_roll_joint" type="fixed">
		<origin xyz="0 0 0" rpy="0 0 0" />
		<parent link="l_ankle_pitch_link" />
		<child link="l_ankle_roll_link" />
		<axis xyz="1 0 0" />
		<limit lower="-0.5" upper="0.2" effort="21" velocity="21" />
	</joint>
</robot>